Workbook

Sheet Raw Data 1
A1: Sl. No. | B1: Arrival Time | C1: Arrival Time | D1: Vehicle Type | E1: State Registered | F1: Car No. | G1: Pump No. | H1: Service Starting | I1: Fuel Type | J1: Gender of Driver | K1: Amount Filled | L1: Payment Mode | M1: Air filled? | N1: Service Completion | O1: vechile info link | P1: Registration type | Q1: No. of Chalans | R1: Insurance Status | S1: City Name | T1: BRAND | U1: MODEL | V1: vehicle details | X1: Pump No. | Y1: Fuel type | Z1: No. of vehicle
A2: 1 | B2: 0.79335362 | C2: 0.7930064 | D2: Bike | E2: J&K | F2: JK 02 BJ 6083 | G2: 2 | H2: 0.79444444 | I2: Petrol | J2: male | K2: 1.04 | L2: Offline | M2: NO | N2: 0.79480324 | O2: https://vehicleinfo.app/rc-details/JK02BJ6083?rc_no=JK02BJ6083 | P2: Private | Q2: 0 | R2: Expired | S2: JAMMU | T2: HERO | U2: SUPER SPLENDER | V2: =HYPERLINK(O2,"link") -> link | X2: 1 | Y2: Diesel | Z2: 15
A3: 2 | B3: 0.79380069 | C3: 0.79345347 | D3: Car | E3: J&K | F3: JK 02 CG 5449 | G3: 2 | H3: 0.79583333 | I3: Petrol | J3: male | K3: 25.9 | L3: Online | M3: NO | N3: 0.79928241 | O3: https://vehicleinfo.app/rc-details/JK02CG5449?rc_no=JK02CG5449 | P3: Private | Q3: 0 | R3: Valid | S3: JAMMU | T3: MARUTI SUZUKI INDIA LTD | U3: MARUTI ALTO K10 VXI | V3: =HYPERLINK(O3,"link") -> link | X3: 2 | Y3: Petrol | Z3: 45
A4: 3 | B4: 0.79421503 | C4: 0.79386781 | D4: Scooter | E4: J&K | F4: JK 02 CN 9553 | G4: 3 | H4: 0.79375 | I4: Petrol | J4: male | K4: 1.04 | L4: Offline | M4: NO | N4: 0.79584491 | O4: https://vehicleinfo.app/rc-details/JK02CN9553?rc_no=JK02CN9553 | P4: Private | Q4: 0 | R4: Valid | S4: JAMMU | T4: HONDA MOTORCYCLE AND SCOOTER INDIA (P) LTD | U4: ACTIVA 6G DLX | V4: =HYPERLINK(O4,"link") -> link | X4: 3 | Y4: Petrol | Z4: 27
A5: 4 | B5: 0.79523999 | C5: 0.79489277 | D5: auto | E5: J&K | F5: JK 02 BD 4552 | G5: 1 | H5: 0.79513889 | I5: Diesel | J5: male | K5: 5.86 | L5: Offline | M5: NO | N5: 0.79740741 | O5: https://vehicleinfo.app/rc-details/JK02BD4552?rc_no=JK02BD4552 | P5: Taxi | Q5: 1 | R5: Valid | S5: JAMMU | T5: TATA MOTORS LTD | U5: ACE MAGIC EII HT 275 | V5: =HYPERLINK(O5,"link") -> link | X5: 4 | Y5: Petrol | Z5: 15
A6: 5 | B6: 0.7960133 | C6: 0.79566608 | D6: Bike | E6: J&K | F6: JK 20 C 4975 | G6: 2 | H6: 0.79722222 | I6: Petrol | J6: male | K6: 2.59 | L6: Offline | M6: NO | N6: 0.79771991 | O6: https://vehicleinfo.app/rc-details/JK20C4975?rc_no=JK20C4975 | P6: Private | Q6: 0 | R6: Valid | S6: RESAI | T6: TVS | U6: TVS RADEON | V6: =HYPERLINK(O6,"link") -> link | X6: 5 | Y6: Diesel | Z6: 2
A7: 6 | B7: 0.79684441 | C7: 0.79649719 | D7: Car | E7: J&K | F7: JK 20 B 0450 | G7: 3 | H7: 0.79791667 | I7: Petrol | J7: male | K7: 20.73 | L7: Online | M7: NO | N7: 0.80009259 | O7: https://vehicleinfo.app/rc-details/JK20B0450?rc_no=JK20B0450 | P7: Private | Q7: 3 | R7: Expired | S7: RESAI | T7: MARUTI SUZUKI INDIA LTD | U7: MARUTI SWIFT VXI | V7: =HYPERLINK(O7,"link") -> link | Z7: =sum(Z2:Z6) -> 104
A8: 7 | B8: 0.79686999 | C8: 0.79652277 | D8: Bike | E8: J&K | F8: JK 02 C 0391 | G8: 4 | H8: 0.79791667 | I8: Petrol | J8: male | K8: 1.04 | L8: Online | M8: NO | N8: 0.79832176 | O8: https://vehicleinfo.app/rc-details/JK02C0391?rc_no=JK02C0391 | Q8: NO INFO | R8: NO INFO | S8: JAMMU | T8: NO INFO | V8: =HYPERLINK(O8,"link") -> link
A9: 8 | B9: 0.79692546 | C9: 0.79657824 | D9: Car | E9: J&K | F9: JK 02 AU 2174 | G9: 2 | H9: 0.79791667 | I9: Petrol | J9: male | K9: 19.7 | L9: CARD | M9: NO | N9: 0.80018519 | O9: https://vehicleinfo.app/rc-details/JK02AU2174?rc_no=JK02AU2174 | P9: Private | Q9: 0 | R9: Expired | S9: JAMMU | T9: ALTO K10B VXI | U9: ALTO K10B VXI | V9: =HYPERLINK(O9,"link") -> link
A10: 9 | B10: 0.79843575 | C10: 0.79808853 | D10: Bike | E10: J&K | F10: JK 02 CT 3239 | G10: 3 | H10: 0.79930556 | I10: Petrol | J10: male | K10: 3.11 | L10: Offline | M10: NO | N10: 0.79998843 | O10: https://vehicleinfo.app/rc-details/JK02CT3239?rc_no=JK02CT3239 | P10: Private | Q10: 9 | R10: Valid | S10: JAMMU | T10: HERO MOTOCORP LTD | U10: SPLENDOR | V10: =HYPERLINK(O10,"link") -> link
A11: 10 | B11: 0.79866748 | C11: 0.79832025 | D11: Scooter | E11: J&K | F11: JK 20 L 9880 | G11: 2 | H11: 0.79930556 | I11: Petrol | J11: male | K11: 2.07 | L11: Offline | M11: NO | N11: 0.80063657 | O11: https://vehicleinfo.app/rc-details/JK020L9880?rc_no=JK020L9880 | P11: Private | Q11: NO INFO | R11: NO INFO | S11: RESAI | T11: NO INFO | V11: =HYPERLINK(O11,"link") -> link
A12: 11 | B12: 0.79941537 | C12: 0.79906815 | D12: Bike | E12: J&K | F12: JK 20 C 1155 | G12: 3 | H12: 0.79930556 | I12: Petrol | J12: male | K12: 1.04 | L12: Offline | M12: NO | N12: 0.80091435 | O12: https://vehicleinfo.app/rc-details/JK20C1155?rc_no=JK20C1155 | P12: Private | Q12: 0 | R12: Valid | S12: RESAI | T12: ROYAL-ENFIELD (UNIT OF EICHER LTD) | U12: BULLET 350 EFI | V12: =HYPERLINK(O12,"link") -> link
A13: 12 | B13: 0.8030125 | C13: 0.80266528 | D13: Car | E13: J&K | F13: JK 02 AT 2503 | G13: 2 | H13: 0.80277778 | I13: Petrol | J13: male | K13: 5.18 | L13: Offline | M13: NO | N13: 0.80394676 | O13: https://vehicleinfo.app/rc-details/JK02AT2503?rc_no=JK02AT2503 | P13: Private | Q13: 0 | R13: Expired | S13: JAMMU | T13: MARUTI SUZUKI INDIA LTD | U13: ALTO LXI | V13: =HYPERLINK(O13,"link") -> link
A14: 13 | B14: 0.80326582 | C14: 0.8029186 | D14: Bike | E14: J&K | F14: JK 02 DL 4581 | G14: 3 | H14: 0.80555556 | I14: Petrol | J14: male | K14: 1.04 | L14: Offline | M14: NO | N14: 0.80670139 | O14: https://vehicleinfo.app/rc-details/JK02DL4581?rc_no=JK02DL4581 | P14: Private | Q14: 0 | R14: Valid | S14: JAMMU | T14: HERO | U14: SUPER SPLENDOR XTEC DR | V14: =HYPERLINK(O14,"link") -> link
A15: 14 | B15: 0.80683963 | C15: 0.80649241 | D15: Car | E15: J&K | F15: JK 02 DR 5589 | G15: 3 | H15: 0.80694444 | I15: Petrol | J15: male | K15: 5.18 | L15: Offline | M15: NO | N15: 0.8078588 | O15: https://vehicleinfo.app/rc-details/JK02DR5589?rc_no=JK02DR5589 | P15: Private | Q15: 0 | R15: Valid | S15: JAMMU | T15: MARUTI SUZUKI INDIA LTD | U15: BALENO DELTA | V15: =HYPERLINK(O15,"link") -> link
A16: 15 | B16: 0.80710627 | C16: 0.80675905 | D16: Tractor | E16: J&K | F16: JK 02 DP 1085 | G16: 1 | H16: 0.80763889 | I16: Diesel | J16: male | K16: 9.38 | L16: Offline | M16: NO | N16: 0.80953704 | O16: https://vehicleinfo.app/rc-details/JK02DP1085?rc_no=JK02DP1085 | P16: Private | Q16: 0 | R16: Expired | S16: JAMMU | T16: MAHINDRA | U16: SWARAJ 735 FE V1 | V16: =HYPERLINK(O16,"link") -> link
A17: 16 | B17: 0.8075463 | C17: 0.80719907 | D17: PICK UP | E17: J&K | F17: JK 02 BE 0139 | G17: 2 | H17: 0.80763889 | I17: Petrol | J17: male | K17: 1.04 | L17: Offline | M17: NO | N17: 0.8083912 | O17: https://vehicleinfo.app/rc-details/JK02BE0139?rc_no=JK02BE0139 | P17: Private | Q17: 0 | R17: Valid | S17: JAMMU | T17: MAHINDRA & MAHINDRA LIMITED | U17: BOLERO ZLX | V17: =HYPERLINK(O17,"link") -> link
A18: 17 | B18: 0.80861725 | C18: 0.80827002 | D18: Bike | E18: J&K | F18: JK 14E 0406 | G18: 2 | H18: 0.80833333 | I18: Petrol | J18: male | K18: 6.22 | L18: Offline | M18: NO | N18: 0.81 | O18: https://vehicleinfo.app/rc-details/JK14E0406?rc_no=JK14E0406 | P18: Private | Q18: 0 | R18: Valid | S18: UDHAMPUR | T18: MARUTI SUZUKI INDIA LTD | U18: SWIFT LXI | V18: =HYPERLINK(O18,"link") -> link
A19: 18 | B19: 0.80993115 | C19: 0.80958392 | D19: Bike | E19: J&K | F19: JK 02 CU 4173 | G19: 2 | H19: 0.80902778 | I19: Petrol | J19: male | K19: 1.97 | L19: Offline | M19: NO | N19: 0.81 | O19: https://vehicleinfo.app/rc-details/JK02CU4173?rc_no=JK02CU4173 | P19: Private | Q19: 0 | R19: Valid | S19: JAMMU | T19: TVS MOTOR COMPANY LTD / TVS APACHE RTR 2 4V | U19: TVS APACHE RTR 200 4V | V19: =HYPERLINK(O19,"link") -> link
A20: 19 | B20: 0.80995434 | C20: 0.80960712 | D20: Car | E20: J&K | F20: JK 02 BQ 2567 | G20: 2 | H20: 0.80972222 | I20: Petrol | J20: male | K20: 5.18 | L20: Offline | M20: NO | N20: 0.8109375 | O20: https://vehicleinfo.app/rc-details/JK02BQ2567?rc_no=JK02BQ2567 | P20: Private | Q20: 0 | R20: Valid | S20: JAMMU | T20: MARUTI SUZUKI INDIA LTD | U20: ALTO 800 LXI | V20: =HYPERLINK(O20,"link") -> link
A21: 20 | B21: 0.81060603 | C21: 0.81025881 | D21: Bike | E21: J&K | F21: JK 02 AD 9993 | G21: 2 | H21: 0.81041667 | I21: Petrol | J21: male | K21: 2.07 | L21: Online | M21: NO | N21: 0.81207176 | O21: https://vehicleinfo.app/rc-details/JK02AD9993?rc_no=JK02AD9993 | P21: Private | Q21: 0 | R21: Valid | S21: JAMMU | T21: BAJAJ AUTO LTD | U21: PLATINA | V21: =HYPERLINK(O21,"link") -> link
A22: 21 | B22: 0.81086039 | C22: 0.81051317 | D22: Car | E22: J&K | F22: JK 02 CF 3468 | G22: 2 | H22: 0.81111111 | I22: Petrol | J22: male | K22: 5.18 | L22: Offline | M22: NO | N22: 0.81217593 | O22: https://vehicleinfo.app/rc-details/JK02CF3468?rc_no=JK02CF3468 | P22: Private | Q22: 1 | R22: Expired | S22: JAMMU | T22: HYUNDAIMOTOR | U22: EON ERA+ | V22: =HYPERLINK(O22,"link") -> link
A23: 22 | B23: 0.81152988 | C23: 0.81118266 | D23: Car | E23: J&K | F23: JK 02 DS 7236 | G23: 2 | H23: 0.81180556 | I23: Petrol | J23: male | K23: 20.73 | L23: Offline | M23: NO | O23: https://vehicleinfo.app/rc-details/JK02DS7236?rc_no=JK02DS7236 | P23: Private | Q23: 0 | R23: Valid | S23: JAMMU | T23: MARUTI SUZUKI INDIA LTD | U23: ALTO K10 LXI | V23: =HYPERLINK(O23,"link") -> link
A24: 23 | B24: 0.81164595 | C24: 0.81129873 | D24: Car | E24: J&K | F24: JK 02 CS 5994 | G24: 2 | H24: 0.8125 | I24: Petrol | J24: male | K24: 32.14 | L24: CARD | M24: NO | N24: 0.81515046 | O24: https://vehicleinfo.app/rc-details/JK02CS5994?rc_no=JK02CS5994 | P24: Private | Q24: 0 | R24: Expired | S24: JAMMU | T24: MARUTI SUZUKI INDIA LTD | U24: SWIFT ZXI | V24: =HYPERLINK(O24,"link") -> link
A25: 24 | B25: 0.81235764 | C25: 0.81201042 | D25: Bike | E25: J&K | F25: JK 02 CF2800 | G25: 3 | H25: 0.81388889 | I25: Petrol | J25: male | K25: 5.18 | L25: Offline | M25: NO | N25: 0.81494213 | O25: https://vehicleinfo.app/rc-details/JK02F2800?rc_no=JK02F2800 | P25: Private | Q25: 13 | R25: Expired | S25: JAMMU | T25: ROYAL-ENFIELD (UNIT OF EICHER LTD) | U25: CLASSIC 350 | V25: link
A26: 25 | B26: 0.81238113 | C26: 0.81203391 | D26: Scooter | E26: J&K | F26: JK 02 CH 7778 | G26: 4 | H26: 0.81388889 | I26: Petrol | J26: male | K26: 0.8 | L26: Online | M26: NO | O26: https://vehicleinfo.app/rc-details/JK02CH7778?rc_no=JK02CH7778 | P26: Private | Q26: 0 | R26: Expired | S26: JAMMU | T26: MARUTI SUZUKI INDIA LTD | U26: BALENO DELTA | V26: =HYPERLINK(O26,"link") -> link
A27: 26 | B27: 0.81261097 | C27: 0.81226375 | D27: Car | E27: J&K | F27: JK 02 AH 0922 | G27: 3 | H27: 0.8125 | I27: Petrol | J27: male | K27: 2.07 | L27: Online | M27: NO | N27: 0.81394676 | O27: https://vehicleinfo.app/rc-details/JK02AH0922?rc_no=JK02AH0922 | P27: Private | Q27: 0 | R27: Expired | S27: JAMMU | T27: HYUNDAIMOTORI | U27: i10 ERA | V27: =HYPERLINK(O27,"link") -> link
A28: 27 | B28: 0.81316975 | C28: 0.81282252 | D28: Car | E28: J&K | F28: JK 02 DG 2001 | G28: 4 | H28: 0.81597222 | I28: Petrol | J28: male | K28: 5.18 | L28: Online | M28: NO | N28: 0.81696759 | O28: https://vehicleinfo.app/rc-details/JK02DG2001?rc_no=JK02DG2001 | P28: Private | Q28: 0 | R28: Valid | S28: JAMMU | T28: MARUTI SUZUKI INDIA LTD | U28: G VITARA | V28: =HYPERLINK(O28,"link") -> link
A29: 28 | B29: 0.81325889 | C29: 0.81291167 | D29: Car | E29: J&K | F29: JK 02 BK 4144 | G29: 2 | H29: 0.81458333 | I29: Petrol | J29: male | K29: 10.38 | L29: Offline | M29: NO | N29: 0.81592593 | O29: https://vehicleinfo.app/rc-details/JK02BK4144?rc_no=JK02BK4144 | P29: Private | Q29: 0 | R29: Valid | S29: JAMMU | T29: MARUTI SUZUKI INDIA LTD | U29: SWIFT DZIRE | V29: =HYPERLINK(O29,"link") -> link
A30: 29 | B30: 0.81386066 | C30: 0.81351344 | D30: Car | E30: J&K | F30: JK 21 F 0277 | G30: 1 | H30: 0.81597222 | I30: Diesel | J30: male | K30: 11.72 | L30: Online | M30: NO | N30: 0.81724537 | O30: https://vehicleinfo.app/rc-details/JK21F0277?rc_no=JK21F0277 | P30: Private | Q30: 0 | R30: Valid | S30: SAMBA | T30: MAHINDRA & MAHINDRA LIMITED | U30: MAHINDRA BOLERO POWER+ ZLX MH | V30: =HYPERLINK(O30,"link") -> link
A31: 30 | B31: 0.81387811 | C31: 0.81353089 | D31: Bike | E31: Other | F31: HR 26 DA 9335 | G31: 2 | H31: 0.81458333 | I31: Petrol | J31: male | K31: 1.49 | L31: Offline | M31: NO | N31: 0.81561343 | O31: https://vehicleinfo.app/rc-details/HR26DA9335?rc_no=HR26DA9335 | P31: Private | Q31: 1 | R31: Expired | S31: GURUGAM | T31: ROYAL ENFIELD | U31: ENFIELD 350 CC | V31: =HYPERLINK(O31,"link") -> link
A32: 31 | B32: 0.81429596 | C32: 0.81394874 | D32: Bike | E32: J&K | F32: JK 02 AH 4611 | G32: 3 | H32: 0.81458333 | I32: Petrol | J32: male | K32: 1.76 | L32: Offline | M32: NO | N32: 0.81576389 | O32: https://vehicleinfo.app/rc-details/JK02AH4611?rc_no=JK02AH4611 | P32: Private | Q32: 0 | R32: Expired | S32: JAMMU | T32: HERO HONDA MOTORS LTD | U32: HERO HONDA PASSION PLUS | V32: =HYPERLINK(O32,"link") -> link
A33: 32 | B33: 0.81509609 | C33: 0.81474887 | D33: Car | E33: J&K | F33: JK 02 AW 2131 | G33: 2 | H33: 0.81597222 | I33: Petrol | J33: male | K33: 7.28 | L33: Online | M33: NO | N33: 0.81710648 | O33: https://vehicleinfo.app/rc-details/JK02AW2131?rc_no=JK02AW2131 | P33: Private | Q33: 0 | R33: Valid | S33: JAMMU | T33: HYUNDAI MOTOR INDIA LTD | U33: SANTRO GLS | V33: =HYPERLINK(O33,"link") -> link
A34: 33 | B34: 0.81589198 | C34: 0.81554476 | D34: Car | E34: J&K | F34: JK 02 DU 0772 | G34: 3 | H34: 0.81527778 | I34: Petrol | J34: male | K34: 18.8 | L34: Online | M34: NO | N34: 0.81716435 | O34: https://vehicleinfo.app/rc-details/JK02DU0772?rc_no=JK02DU0772 | P34: Private | Q34: 0 | R34: Valid | S34: JAMMU | T34: TOYOTA KIRLOSKAR MOTOR PVT LTD | U34: ETIOS G PETROL KI | V34: =HYPERLINK(O34,"link") -> link
A35: 34 | B35: 0.81606282 | C35: 0.8157156 | D35: Car | E35: J&K | F35: JK 02 DC 5415 | G35: 2 | H35: 0.81736111 | I35: Petrol | J35: male | K35: 5.18 | L35: Offline | M35: NO | N35: 0.81818287 | O35: https://vehicleinfo.app/rc-details/JK02DC5415?rc_no=JK02DC5415 | P35: Private | Q35: 0 | R35: Valid | S35: JAMMU | T35: TATA MOTORS PASSENGER VEHICLES LTD | U35: TIAGO XT NEW 1.2 RTN BS6 | V35: =HYPERLINK(O35,"link") -> link
A36: 35 | B36: 0.81740903 | C36: 0.81706181 | D36: Car | E36: J&K | F36: JK 02 DN 3352 | G36: 3 | H36: 0.81736111 | I36: Petrol | J36: male | K36: 20.73 | L36: Offline | M36: NO | N36: 0.81903935 | O36: https://vehicleinfo.app/rc-details/JK02DN3352?rc_no=JK02DN3352 | P36: Private | Q36: 0 | R36: Valid | S36: JAMMU | T36: MARUTI SUZUKI INDIA LTD | U36: BREZZA LXI | V36: =HYPERLINK(O36,"link") -> link
A37: 36 | B37: 0.8184305 | C37: 0.81808328 | D37: trucks | E37: J&K | F37: JK 02 DK 0331 | G37: 1 | H37: 0.81875 | I37: Diesel | J37: male | K37: 21.09 | L37: Offline | M37: NO | N37: 0.8208912 | O37: https://vehicleinfo.app/rc-details/JK02DK0331?rc_no=JK02DK0331 | P37: Private | Q37: 0 | R37: Valid | S37: JAMMU | T37: TATA MOTORS LTD | U37: 407 GOLD SFC DCR33CBC 100B6M5 | V37: =HYPERLINK(O37,"link") -> link
A38: 37 | B38: 0.81865182 | C38: 0.81830459 | D38: Scooter | E38: J&K | F38: JK 02 BR 0955 | G38: 2 | H38: 0.81805556 | I38: Petrol | J38: male | K38: 3.11 | L38: Offline | M38: NO | N38: 0.81945602 | O38: https://vehicleinfo.app/rc-details/JK02BR0955?rc_no=JK02BR0955 | P38: Private | Q38: 0 | R38: Expired | S38: JAMMU | T38: Hero MotoCorp Ltd | U38: MESTRO EDGE | V38: =HYPERLINK(O38,"link") -> link
... A42: 41 | B42: 0.82387144 | C42: 0.82352421 | D42: Car | E42: J&K | F42: JK 02 AU 3557 | G42: 2 | H42: 0.82430556 | I42: Petrol | J42: male | K42: 4.15 | L42: Offline | M42: NO | N42: 0.82528935 | O42: https://vehicleinfo.app/rc-details/JK02AU3557?rc_no=JK02AU3557 | P42: Private | Q42: 0 | R42: Expired | S42: JAMMU | T42: MARUTI SUZUKI INDIA LTD | U42: 800 MPI AC | V42: =HYPERLINK(O42,"link") -> link
A43: 42 | B43: 0.82418314 | C43: 0.82383591 | D43: Scooter | E43: J&K | F43: JK 02 8463 | G43: 4 | H43: 0.82708333 | I43: Petrol | J43: male | K43: 2.07 | L43: Offline | M43: NO | N43: 0.82844907 | O43: https://vehicleinfo.app/rc-details/JK028463?rc_no=JK028463 | Q43: NO INFO | R43: NO INFO | S43: JAMMU | T43: #VALUE! | V43: =HYPERLINK(O43,"link") -> link
...

Sheet Raw Data 2
A1: Sl. No. | B1: Arrival Time | C1: Arrival Time | D1: Arrival Time | E1: IAT | F1: Duration start time | G1: Vehicle Type | H1: State Registered | I1: Car No. | J1: Pump No. | K1: Service Starting | L1: SST | M1: Fuel Type | N1: Gender of Driver | O1: Amount Filled | P1: Amount Paid | Q1: Payment Mode | R1: Air filled? | S1: Service Completion | T1: SCT | U1: service Time | V1: vechile info link | W1: Registration type | X1: No. of Chalans | Y1: Insurance Status | Z1: City Name | AA1: BRAND | AB1: MODEL | AC1: vehicle details
A2: 1 | B2: 0.79335362 | C2: 0.7930064 | D2: =C2-time(0,0,30) -> 0.79265918 | E2: =D3-D2 -> 0.00044707176 | F2: =D2-TIME(19,1,25) -> 8.7152773e-06 | G2: Bike | H2: J&K | I2: JK 02 BJ 6083 | J2: 2 | K2: 0.79444444 | L2: =K2-TIME(19,1,25) -> 0.0017939815 | M2: Petrol | N2: male | O2: 1.04 | P2: 100.3808 | Q2: Offline | R2: NO | S2: 0.79480324 | T2: =S2-TIME(19,1,25) -> 0.0021527778 | U2: =T2-L2 -> 0.0003587963 | V2: https://vehicleinfo.app/rc-details/JK02BJ6083?rc_no=JK02BJ6083 | W2: Private | X2: 0 | Y2: Expired | Z2: JAMMU | AA2: HERO | AB2: SUPER SPLENDER | AC2: =HYPERLINK(V2,"link") -> link
A3: 2 | B3: 0.79380069 | C3: 0.79345347 | D3: =C3-time(0,0,30) -> 0.79310625 | E3: =D4-D3 -> 0.00041434028 | F3: =D3-TIME(19,1,25) -> 0.00045578704 | G3: Car | H3: J&K | I3: JK 02 CG 5449 | J3: 2 | K3: 0.79583333 | L3: =K3-TIME(19,1,25) -> 0.0031828704 | M3: Petrol | N3: male | O3: 25.9 | P3: 2499.868 | Q3: Online | R3: NO | S3: 0.79928241 | T3: =S3-TIME(19,1,25) -> 0.0066319444 | U3: =T3-L3 -> 0.0034490741 | V3: https://vehicleinfo.app/rc-details/JK02CG5449?rc_no=JK02CG5449 | W3: Private | X3: 0 | Y3: Valid | Z3: JAMMU | AA3: MARUTI SUZUKI INDIA LTD | AB3: MARUTI ALTO K10 VXI | AC3: =HYPERLINK(V3,"link") -> link
A4: 3 | B4: 0.79421503 | C4: 0.79386781 | D4: =C4-time(0,0,30) -> 0.79352059 | E4: =D5-D4 -> 0.0010249537 | F4: =D4-TIME(19,1,25) -> 0.00087012732 | G4: Scooter | H4: J&K | I4: JK 02 CN 9553 | J4: 3 | K4: 0.79375 | L4: =K4-TIME(19,1,25) -> 0.001099537 | M4: Petrol | N4: male | O4: 1.04 | P4: 100.3808 | Q4: Offline | R4: NO | S4: 0.79584491 | T4: =S4-TIME(19,1,25) -> 0.0031944444 | U4: =T4-L4 -> 0.0020949074 | V4: https://vehicleinfo.app/rc-details/JK02CN9553?rc_no=JK02CN9553 | W4: Private | X4: 0 | Y4: Valid | Z4: JAMMU | AA4: HONDA MOTORCYCLE AND SCOOTER INDIA (P) LTD | AB4: ACTIVA 6G DLX | AC4: =HYPERLINK(V4,"link") -> link
A5: 4 | B5: 0.79523999 | C5: 0.79489277 | D5: =C5-time(0,0,30) -> 0.79454554 | E5: =D6-D5 -> 0.00077331019 | F5: =D5-TIME(19,1,25) -> 0.001895081 | G5: auto | H5: J&K | I5: JK 02 BD 4552 | J5: 1 | K5: 0.79513889 | L5: =K5-TIME(19,1,25) -> 0.0024884259 | M5: Diesel | N5: male | O5: 5.86 | P5: =O5*85.325 -> 500.0045 | Q5: Offline | R5: NO | S5: 0.79740741 | T5: =S5-TIME(19,1,25) -> 0.0047569444 | U5: =T5-L5 -> 0.0022685185 | V5: https://vehicleinfo.app/rc-details/JK02BD4552?rc_no=JK02BD4552 | W5: Taxi | X5: 1 | Y5: Valid | Z5: JAMMU | AA5: TATA MOTORS LTD | AB5: ACE MAGIC EII HT 275 | AC5: =HYPERLINK(V5,"link") -> link
A6: 5 | B6: 0.7960133 | C6: 0.79566608 | D6: =C6-time(0,0,30) -> 0.79531885 | E6: =D7-D6 -> 0.00083111111 | F6: =D6-TIME(19,1,25) -> 0.0026683912 | G6: Bike | H6: J&K | I6: JK 20 C 4975 | J6: 2 | K6: 0.79722222 | L6: =K6-TIME(19,1,25) -> 0.0045717593 | M6: Petrol | N6: male | O6: 2.59 | P6: 249.9868 | Q6: Offline | R6: NO | S6: 0.79771991 | T6: =S6-TIME(19,1,25) -> 0.0050694444 | U6: =T6-L6 -> 0.00049768519 | V6: https://vehicleinfo.app/rc-details/JK20C4975?rc_no=JK20C4975 | W6: Private | X6: 0 | Y6: Valid | Z6: RESAI | AA6: TVS | AB6: TVS RADEON | AC6: =HYPERLINK(V6,"link") -> link
A7: 6 | B7: 0.79684441 | C7: 0.79649719 | D7: =C7-time(0,0,30) -> 0.79614997 | E7: =D8-D7 -> 2.5578702e-05 | F7: =D7-TIME(19,1,25) -> 0.0034995023 | G7: Car | H7: J&K | I7: JK 20 B 0450 | J7: 3 | K7: 0.79791667 | L7: =K7-TIME(19,1,25) -> 0.0052662037 | M7: Petrol | N7: male | O7: 20.73 | P7: 2000 | Q7: Online | R7: NO | S7: 0.80009259 | T7: =S7-TIME(19,1,25) -> 0.0074421296 | U7: =T7-L7 -> 0.0021759259 | V7: https://vehicleinfo.app/rc-details/JK20B0450?rc_no=JK20B0450 | W7: Private | X7: 3 | Y7: Expired | Z7: RESAI | AA7: MARUTI SUZUKI INDIA LTD | AB7: MARUTI SWIFT VXI | AC7: =HYPERLINK(V7,"link") -> link
A8: 7 | B8: 0.79686999 | C8: 0.79652277 | D8: =C8-time(0,0,30) -> 0.79617554 | E8: =D9-D8 -> 5.5474542e-05 | F8: =D8-TIME(19,1,25) -> 0.003525081 | G8: Bike | H8: J&K | I8: JK 02 C 0391 | J8: 4 | K8: 0.79791667 | L8: =K8-TIME(19,1,25) -> 0.0052662037 | M8: Petrol | N8: male | O8: 1.04 | P8: 99.996 | Q8: Online | R8: NO | S8: 0.79832176 | T8: =S8-TIME(19,1,25) -> 0.0056712963 | U8: =T8-L8 -> 0.00040509259 | V8: https://vehicleinfo.app/rc-details/JK02C0391?rc_no=JK02C0391 | W8: Private | X8: NO INFO | Y8: NO INFO | Z8: JAMMU | AA8: NO INFO | AC8: =HYPERLINK(V8,"link") -> link
A9: 8 | B9: 0.79692546 | C9: 0.79657824 | D9: =C9-time(0,0,30) -> 0.79623102 | E9: =D10-D9 -> 0.0015102894 | F9: =D9-TIME(19,1,25) -> 0.0035805556 | G9: Car | H9: J&K | I9: JK 02 AU 2174 | J9: 2 | K9: 0.79791667 | L9: =K9-TIME(19,1,25) -> 0.0052662037 | M9: Petrol | N9: male | O9: 19.7 | P9: 1900 | Q9: CARD | R9: NO | S9: 0.80018519 | T9: =S9-TIME(19,1,25) -> 0.0075347222 | U9: =T9-L9 -> 0.0022685185 | V9: https://vehicleinfo.app/rc-details/JK02AU2174?rc_no=JK02AU2174 | W9: Private | X9: 0 | Y9: Expired | Z9: JAMMU | AA9: ALTO K10B VXI | AB9: ALTO K10B VXI | AC9: =HYPERLINK(V9,"link") -> link
A10: 9 | B10: 0.79843575 | C10: 0.79808853 | D10: =C10-time(0,0,30) -> 0.79774131 | E10: =D11-D10 -> 0.00023172453 | F10: =D10-TIME(19,1,25) -> 0.0050908449 | G10: Bike | H10: J&K | I10: JK 02 CT 3239 | J10: 3 | K10: 0.79930556 | L10: =K10-TIME(19,1,25) -> 0.0066550926 | M10: Petrol | N10: male | O10: 3.11 | P10: 300.1772 | Q10: Offline | R10: NO | S10: 0.79998843 | T10: =S10-TIME(19,1,25) -> 0.007337963 | U10: =T10-L10 -> 0.00068287037 | V10: https://vehicleinfo.app/rc-details/JK02CT3239?rc_no=JK02CT3239 | W10: Private | X10: 9 | Y10: Valid | Z10: JAMMU | AA10: HERO MOTOCORP LTD | AB10: SPLENDOR | AC10: =HYPERLINK(V10,"link") -> link
A11: 10 | B11: 0.79866748 | C11: 0.79832025 | D11: =C11-time(0,0,30) -> 0.79797303 | E11: =D12-D11 -> 0.00074789352 | F11: =D11-TIME(19,1,25) -> 0.0053225694 | G11: Scooter | H11: J&K | I11: JK 20 L 9880 | J11: 2 | K11: 0.79930556 | L11: =K11-TIME(19,1,25) -> 0.0066550926 | M11: Petrol | N11: male | O11: 2.07 | P11: 199.7964 | Q11: Offline | R11: NO | S11: 0.80063657 | T11: =S11-TIME(19,1,25) -> 0.0079861111 | U11: =T11-L11 -> 0.0013310185 | V11: https://vehicleinfo.app/rc-details/JK020L9880?rc_no=JK020L9880 | W11: Private | X11: NO INFO | Y11: NO INFO | Z11: RESAI | AA11: NO INFO | AC11: =HYPERLINK(V11,"link") -> link
A12: 11 | B12: 0.79941537 | C12: 0.79906815 | D12: =C12-time(0,0,30) -> 0.79872093 | E12: =D13-D12 -> 0.0035971296 | F12: =D12-TIME(19,1,25) -> 0.006070463 | G12: Bike | H12: J&K | I12: JK 20 C 1155 | J12: 3 | K12: 0.79930556 | L12: =K12-TIME(19,1,25) -> 0.0066550926 | M12: Petrol | N12: male | O12: 1.04 | P12: 100.3808 | Q12: Offline | R12: NO | S12: 0.80091435 | T12: =S12-TIME(19,1,25) -> 0.0082638889 | U12: =T12-L12 -> 0.0016087963 | V12: https://vehicleinfo.app/rc-details/JK20C1155?rc_no=JK20C1155 | W12: Private | X12: 0 | Y12: Valid | Z12: RESAI | AA12: ROYAL-ENFIELD (UNIT OF EICHER LTD) | AB12: BULLET 350 EFI | AC12: =HYPERLINK(V12,"link") -> link
A13: 12 | B13: 0.8030125 | C13: 0.80266528 | D13: =C13-time(0,0,30) -> 0.80231806 | E13: =D14-D13 -> 0.00025332176 | F13: =D13-TIME(19,1,25) -> 0.0096675926 | G13: Car | H13: J&K | I13: JK 02 AT 2503 | J13: 2 | K13: 0.80277778 | L13: =K13-TIME(19,1,25) -> 0.010127315 | M13: Petrol | N13: male | O13: 5.18 | P13: 499.9736 | Q13: Offline | R13: NO | S13: 0.80394676 | T13: =S13-TIME(19,1,25) -> 0.011296296 | U13: =T13-L13 -> 0.0011689815 | V13: https://vehicleinfo.app/rc-details/JK02AT2503?rc_no=JK02AT2503 | W13: Private | X13: 0 | Y13: Expired | Z13: JAMMU | AA13: MARUTI SUZUKI INDIA LTD | AB13: ALTO LXI | AC13: =HYPERLINK(V13,"link") -> link
A14: 13 | B14: 0.80326582 | C14: 0.8029186 | D14: =C14-time(0,0,30) -> 0.80257138 | E14: =D15-D14 -> 0.0035738079 | F14: =D14-TIME(19,1,25) -> 0.0099209143 | G14: Bike | H14: J&K | I14: JK 02 DL 4581 | J14: 3 | K14: 0.80555556 | L14: =K14-TIME(19,1,25) -> 0.012905093 | M14: Petrol | N14: male | O14: 1.04 | P14: 99.996 | Q14: Offline | R14: NO | S14: 0.80670139 | T14: =S14-TIME(19,1,25) -> 0.014050926 | U14: =T14-L14 -> 0.0011458333 | V14: https://vehicleinfo.app/rc-details/JK02DL4581?rc_no=JK02DL4581 | W14: Private | X14: 0 | Y14: Valid | Z14: JAMMU | AA14: HERO | AB14: SUPER SPLENDOR XTEC DR | AC14: =HYPERLINK(V14,"link") -> link
A15: 14 | B15: 0.80683963 | C15: 0.80649241 | D15: =C15-time(0,0,30) -> 0.80614519 | E15: =D16-D15 -> 0.00026664352 | F15: =D15-TIME(19,1,25) -> 0.013494722 | G15: Car | H15: J&K | I15: JK 02 DR 5589 | J15: 3 | K15: 0.80694444 | L15: =K15-TIME(19,1,25) -> 0.014293981 | M15: Petrol | N15: male | O15: 5.18 | P15: 499.9736 | Q15: Offline | R15: NO | S15: 0.8078588 | T15: =S15-TIME(19,1,25) -> 0.015208333 | U15: =T15-L15 -> 0.00091435185 | V15: https://vehicleinfo.app/rc-details/JK02DR5589?rc_no=JK02DR5589 | W15: Private | X15: 0 | Y15: Valid | Z15: JAMMU | AA15: MARUTI SUZUKI INDIA LTD | AB15: BALENO DELTA | AC15: =HYPERLINK(V15,"link") -> link
A16: 15 | B16: 0.80710627 | C16: 0.80675905 | D16: =C16-time(0,0,30) -> 0.80641183 | E16: =D17-D16 -> 0.00044002315 | F16: =D16-TIME(19,1,25) -> 0.013761366 | G16: Tractor | H16: J&K | I16: JK 02 DP 1085 | J16: 1 | K16: 0.80763889 | L16: =K16-TIME(19,1,25) -> 0.014988426 | M16: Diesel | N16: male | O16: 9.38 | P16: =O16*85.325 -> 800.3485 | Q16: Offline | R16: NO | S16: 0.80953704 | T16: =S16-TIME(19,1,25) -> 0.016886574 | U16: =T16-L16 -> 0.0018981481 | V16: https://vehicleinfo.app/rc-details/JK02DP1085?rc_no=JK02DP1085 | W16: Private | X16: 0 | Y16: Expired | Z16: JAMMU | AA16: MAHINDRA | AB16: SWARAJ 735 FE V1 | AC16: =HYPERLINK(V16,"link") -> link
A17: 16 | B17: 0.8075463 | C17: 0.80719907 | D17: =C17-time(0,0,30) -> 0.80685185 | E17: =D18-D17 -> 0.0010709491 | F17: =D17-TIME(19,1,25) -> 0.014201389 | G17: PICK UP | H17: J&K | I17: JK 02 BE 0139 | J17: 2 | K17: 0.80763889 | L17: =K17-TIME(19,1,25) -> 0.014988426 | M17: Petrol | N17: male | O17: 1.04 | P17: 100.3808 | Q17: Offline | R17: NO | S17: 0.8083912 | T17: =S17-TIME(19,1,25) -> 0.015740741 | U17: =T17-L17 -> 0.00075231481 | V17: https://vehicleinfo.app/rc-details/JK02BE0139?rc_no=JK02BE0139 | W17: Private | X17: 0 | Y17: Valid | Z17: JAMMU | AA17: MAHINDRA & MAHINDRA LIMITED | AB17: BOLERO ZLX | AC17: =HYPERLINK(V17,"link") -> link
A18: 17 | B18: 0.80861725 | C18: 0.80827002 | D18: =C18-time(0,0,30) -> 0.8079228 | E18: =D19-D18 -> 0.0013139005 | F18: =D18-TIME(19,1,25) -> 0.015272338 | G18: Bike | H18: J&K | I18: JK 14E 0406 | J18: 2 | K18: 0.80833333 | L18: =K18-TIME(19,1,25) -> 0.01568287 | M18: Petrol | N18: male | O18: 6.22 | P18: 600.3544 | Q18: Offline | R18: NO | S18: 0.81 | T18: =S18-TIME(19,1,25) -> 0.017349537 | U18: =T18-L18 -> 0.0016666667 | V18: https://vehicleinfo.app/rc-details/JK14E0406?rc_no=JK14E0406 | W18: Private | X18: 0 | Y18: Valid | Z18: UDHAMPUR | AA18: MARUTI SUZUKI INDIA LTD | AB18: SWIFT LXI | AC18: =HYPERLINK(V18,"link") -> link
A19: 18 | B19: 0.80993115 | C19: 0.80958392 | D19: =C19-time(0,0,30) -> 0.8092367 | E19: =D20-D19 -> 2.3194443e-05 | F19: =D19-TIME(19,1,25) -> 0.016586238 | G19: Bike | H19: J&K | I19: JK 02 CU 4173 | J19: 2 | K19: 0.80902778 | L19: =K19-TIME(19,1,25) -> 0.016377315 | M19: Petrol | N19: male | O19: 1.97 | P19: 190.1444 | Q19: Offline | R19: NO | S19: 0.81 | T19: =S19-TIME(19,1,25) -> 0.017349537 | U19: =T19-L19 -> 0.00097222222 | V19: https://vehicleinfo.app/rc-details/JK02CU4173?rc_no=JK02CU4173 | W19: Private | X19: 0 | Y19: Valid | Z19: JAMMU | AA19: TVS MOTOR COMPANY LTD / TVS APACHE RTR 2 4V | AB19: TVS APACHE RTR 200 4V | AC19: =HYPERLINK(V19,"link") -> link
A20: 19 | B20: 0.80995434 | C20: 0.80960712 | D20: =C20-time(0,0,30) -> 0.8092599 | E20: =D21-D20 -> 0.00065168981 | F20: =D20-TIME(19,1,25) -> 0.016609433 | G20: Car | H20: J&K | I20: JK 02 BQ 2567 | J20: 2 | K20: 0.80972222 | L20: =K20-TIME(19,1,25) -> 0.017071759 | M20: Petrol | N20: male | O20: 5.18 | P20: 499.9736 | Q20: Offline | R20: NO | S20: 0.8109375 | T20: =S20-TIME(19,1,25) -> 0.018287037 | U20: =T20-L20 -> 0.0012152778 | V20: https://vehicleinfo.app/rc-details/JK02BQ2567?rc_no=JK02BQ2567 | W20: Private | X20: 0 | Y20: Valid | Z20: JAMMU | AA20: MARUTI SUZUKI INDIA LTD | AB20: ALTO 800 LXI | AC20: =HYPERLINK(V20,"link") -> link
A21: 20 | B21: 0.81060603 | C21: 0.81025881 | D21: =C21-time(0,0,30) -> 0.80991159 | E21: =D22-D21 -> 0.00025436343 | F21: =D21-TIME(19,1,25) -> 0.017261123 | G21: Bike | H21: J&K | I21: JK 02 AD 9993 | J21: 2 | K21: 0.81041667 | L21: =K21-TIME(19,1,25) -> 0.017766204 | M21: Petrol | N21: male | O21: 2.07 | P21: 200 | Q21: Online | R21: NO | S21: 0.81207176 | T21: =S21-TIME(19,1,25) -> 0.019421296 | U21: =T21-L21 -> 0.0016550926 | V21: https://vehicleinfo.app/rc-details/JK02AD9993?rc_no=JK02AD9993 | W21: Private | X21: 0 | Y21: Valid | Z21: JAMMU | AA21: BAJAJ AUTO LTD | AB21: PLATINA | AC21: =HYPERLINK(V21,"link") -> link
A22: 21 | B22: 0.81086039 | C22: 0.81051317 | D22: =C22-time(0,0,30) -> 0.81016595 | E22: =D23-D22 -> 0.00066949074 | F22: =D22-TIME(19,1,25) -> 0.017515486 | G22: Car | H22: J&K | I22: JK 02 CF 3468 | J22: 2 | K22: 0.81111111 | L22: =K22-TIME(19,1,25) -> 0.018460648 | M22: Petrol | N22: male | O22: 5.18 | P22: 499.9736 | Q22: Offline | R22: NO | S22: 0.81217593 | T22: =S22-TIME(19,1,25) -> 0.019525463 | U22: =T22-L22 -> 0.0010648148 | V22: https://vehicleinfo.app/rc-details/JK02CF3468?rc_no=JK02CF3468 | W22: Private | X22: 1 | Y22: Expired | Z22: JAMMU | AA22: HYUNDAIMOTOR | AB22: EON ERA+ | AC22: =HYPERLINK(V22,"link") -> link
A23: 22 | B23: 0.81152988 | C23: 0.81118266 | D23: =C23-time(0,0,30) -> 0.81083544 | E23: =D24-D23 -> 0.00011606481 | F23: =D23-TIME(19,1,25) -> 0.018184977 | G23: Car | H23: J&K | I23: JK 02 DS 7236 | J23: 2 | K23: 0.81180556 | L23: =K23-TIME(19,1,25) -> 0.019155093 | M23: Petrol | N23: male | O23: 20.73 | P23: 2000 | Q23: Offline | R23: NO | S23: 0.816875 | T23: =S23-TIME(19,1,25) -> 0.024224537 | U23: =T23-L23 -> 0.0050694444 | V23: https://vehicleinfo.app/rc-details/JK02DS7236?rc_no=JK02DS7236 | W23: Private | X23: 0 | Y23: Valid | Z23: JAMMU | AA23: MARUTI SUZUKI INDIA LTD | AB23: ALTO K10 LXI | AC23: =HYPERLINK(V23,"link") -> link
A24: 23 | B24: 0.81164595 | C24: 0.81129873 | D24: =C24-time(0,0,30) -> 0.8109515 | E24: =D25-D24 -> 0.00071168982 | F24: =D24-TIME(19,1,25) -> 0.018301042 | G24: Car | H24: J&K | I24: JK 02 CS 5994 | J24: 2 | K24: 0.8125 | L24: =K24-TIME(19,1,25) -> 0.019849537 | M24: Petrol | N24: male | O24: 32.14 | P24: 3100 | Q24: CARD | R24: NO | S24: 0.81515046 | T24: =S24-TIME(19,1,25) -> 0.0225 | U24: =T24-L24 -> 0.002650463 | V24: https://vehicleinfo.app/rc-details/JK02CS5994?rc_no=JK02CS5994 | W24: Private | X24: 0 | Y24: Expired | Z24: JAMMU | AA24: MARUTI SUZUKI INDIA LTD | AB24: SWIFT ZXI | AC24: =HYPERLINK(V24,"link") -> link
A25: 24 | B25: 0.81235764 | C25: 0.81201042 | D25: =C25-time(0,0,30) -> 0.81166319 | E25: =D26-D25 -> 2.349537e-05 | F25: =D25-TIME(19,1,25) -> 0.019012731 | G25: Bike | H25: J&K | I25: JK 02 CF2800 | J25: 3 | K25: 0.81388889 | L25: =K25-TIME(19,1,25) -> 0.021238426 | M25: Petrol | N25: male | O25: 5.18 | P25: 499.9736 | Q25: Offline | R25: NO | S25: 0.81494213 | T25: =S25-TIME(19,1,25) -> 0.022291667 | U25: =T25-L25 -> 0.0010532407 | V25: https://vehicleinfo.app/rc-details/JK02F2800?rc_no=JK02F2800 | W25: Private | X25: 13 | Y25: Expired | Z25: JAMMU | AA25: ROYAL-ENFIELD (UNIT OF EICHER LTD) | AB25: CLASSIC 350 | AC25: link
A26: 25 | B26: 0.81238113 | C26: 0.81203391 | D26: =C26-time(0,0,30) -> 0.81168669 | E26: =D27-D26 -> 0.00022983796 | F26: =D26-TIME(19,1,25) -> 0.019036227 | G26: Scooter | H26: J&K | I26: JK 02 CH 7778 | J26: 4 | K26: 0.81388889 | L26: =K26-TIME(19,1,25) -> 0.021238426 | M26: Petrol | N26: male | O26: 0.8 | P26: 80 | Q26: Online | R26: NO | S26: 0.81453704 | T26: =S26-TIME(19,1,25) -> 0.021886574 | U26: =T26-L26 -> 0.00064814815 | V26: https://vehicleinfo.app/rc-details/JK02CH7778?rc_no=JK02CH7778 | W26: Private | X26: 0 | Y26: Expired | Z26: JAMMU | AA26: MARUTI SUZUKI INDIA LTD | AB26: BALENO DELTA | AC26: =HYPERLINK(V26,"link") -> link
A27: 26 | B27: 0.81261097 | C27: 0.81226375 | D27: =C27-time(0,0,30) -> 0.81191653 | E27: =D28-D27 -> 0.00055877315 | F27: =D27-TIME(19,1,25) -> 0.019266065 | G27: Car | H27: J&K | I27: JK 02 AH 0922 | J27: 3 | K27: 0.8125 | L27: =K27-TIME(19,1,25) -> 0.019849537 | M27: Petrol | N27: male | O27: 2.07 | P27: 200 | Q27: Online | R27: NO | S27: 0.81394676 | T27: =S27-TIME(19,1,25) -> 0.021296296 | U27: =T27-L27 -> 0.0014467593 | V27: https://vehicleinfo.app/rc-details/JK02AH0922?rc_no=JK02AH0922 | W27: Private | X27: 0 | Y27: Expired | Z27: JAMMU | AA27: HYUNDAIMOTORI | AB27: i10 ERA | AC27: =HYPERLINK(V27,"link") -> link
A28: 27 | B28: 0.81316975 | C28: 0.81282252 | D28: =C28-time(0,0,30) -> 0.8124753 | E28: =D29-D28 -> 8.9143512e-05 | F28: =D28-TIME(19,1,25) -> 0.019824838 | G28: Car | H28: J&K | I28: JK 02 DG 2001 | J28: 4 | K28: 0.81597222 | L28: =K28-TIME(19,1,25) -> 0.023321759 | M28: Petrol | N28: male | O28: 5.18 | P28: 499.9736 | Q28: Online | R28: NO | S28: 0.81696759 | T28: =S28-TIME(19,1,25) -> 0.02431713 | U28: =T28-L28 -> 0.00099537037 | V28: https://vehicleinfo.app/rc-details/JK02DG2001?rc_no=JK02DG2001 | W28: Private | X28: 0 | Y28: Valid | Z28: JAMMU | AA28: MARUTI SUZUKI INDIA LTD | AB28: G VITARA | AC28: =HYPERLINK(V28,"link") -> link
A29: 28 | B29: 0.81325889 | C29: 0.81291167 | D29: =C29-time(0,0,30) -> 0.81256444 | E29: =D30-D29 -> 0.00060177084 | F29: =D29-TIME(19,1,25) -> 0.019913981 | G29: Car | H29: J&K | I29: JK 02 BK 4144 | J29: 2 | K29: 0.81458333 | L29: =K29-TIME(19,1,25) -> 0.02193287 | M29: Petrol | N29: male | O29: 10.38 | P29: 1001.8776 | Q29: Offline | R29: NO | S29: 0.81592593 | T29: =S29-TIME(19,1,25) -> 0.023275463 | U29: =T29-L29 -> 0.0013425926 | V29: https://vehicleinfo.app/rc-details/JK02BK4144?rc_no=JK02BK4144 | W29: Private | X29: 0 | Y29: Valid | Z29: JAMMU | AA29: MARUTI SUZUKI INDIA LTD | AB29: SWIFT DZIRE | AC29: =HYPERLINK(V29,"link") -> link
A30: 29 | B30: 0.81386066 | C30: 0.81351344 | D30: =C30-time(0,0,30) -> 0.81316622 | E30: =D31-D30 -> 1.7453705e-05 | F30: =D30-TIME(19,1,25) -> 0.020515752 | G30: Car | H30: J&K | I30: JK 21 F 0277 | J30: 1 | K30: 0.81597222 | L30: =K30-TIME(19,1,25) -> 0.023321759 | M30: Diesel | N30: male | O30: 11.72 | P30: =O30*85.325 -> 1000.009 | Q30: Online | R30: NO | S30: 0.81724537 | T30: =S30-TIME(19,1,25) -> 0.024594907 | U30: =T30-L30 -> 0.0012731481 | V30: https://vehicleinfo.app/rc-details/JK21F0277?rc_no=JK21F0277 | W30: Private | X30: 0 | Y30: Valid | Z30: SAMBA | AA30: MAHINDRA & MAHINDRA LIMITED | AB30: MAHINDRA BOLERO POWER+ ZLX MH | AC30: =HYPERLINK(V30,"link") -> link
A31: 30 | B31: 0.81387811 | C31: 0.81353089 | D31: =C31-time(0,0,30) -> 0.81318367 | E31: =D32-D31 -> 0.00041784722 | F31: =D31-TIME(19,1,25) -> 0.020533206 | G31: Bike | H31: Other | I31: HR 26 DA 9335 | J31: 2 | K31: 0.81458333 | L31: =K31-TIME(19,1,25) -> 0.02193287 | M31: Petrol | N31: male | O31: 1.49 | P31: 155 | Q31: Offline | R31: NO | S31: 0.81561343 | T31: =S31-TIME(19,1,25) -> 0.022962963 | U31: =T31-L31 -> 0.0010300926 | V31: https://vehicleinfo.app/rc-details/HR26DA9335?rc_no=HR26DA9335 | W31: Private | X31: 1 | Y31: Expired | Z31: GURUGAM | AA31: ROYAL ENFIELD | AB31: ENFIELD 350 CC | AC31: =HYPERLINK(V31,"link") -> link
A32: 31 | B32: 0.81429596 | C32: 0.81394874 | D32: =C32-time(0,0,30) -> 0.81360152 | E32: =D33-D32 -> 0.00080012732 | F32: =D32-TIME(19,1,25) -> 0.020951053 | G32: Bike | H32: J&K | I32: JK 02 AH 4611 | J32: 3 | K32: 0.81458333 | L32: =K32-TIME(19,1,25) -> 0.02193287 | M32: Petrol | N32: male | O32: 1.76 | P32: 169.8752 | Q32: Offline | R32: NO | S32: 0.81576389 | T32: =S32-TIME(19,1,25) -> 0.023113426 | U32: =T32-L32 -> 0.0011805556 | V32: https://vehicleinfo.app/rc-details/JK02AH4611?rc_no=JK02AH4611 | W32: Private | X32: 0 | Y32: Expired | Z32: JAMMU | AA32: HERO HONDA MOTORS LTD | AB32: HERO HONDA PASSION PLUS | AC32: =HYPERLINK(V32,"link") -> link
A33: 32 | B33: 0.81509609 | C33: 0.81474887 | D33: =C33-time(0,0,30) -> 0.81440164 | E33: =D34-D33 -> 0.0007958912 | F33: =D33-TIME(19,1,25) -> 0.021751181 | G33: Car | H33: J&K | I33: JK 02 AW 2131 | J33: 2 | K33: 0.81597222 | L33: =K33-TIME(19,1,25) -> 0.023321759 | M33: Petrol | N33: male | O33: 7.28 | P33: 700 | Q33: Online | R33: NO | S33: 0.81710648 | T33: =S33-TIME(19,1,25) -> 0.024456019 | U33: =T33-L33 -> 0.0011342593 | V33: https://vehicleinfo.app/rc-details/JK02AW2131?rc_no=JK02AW2131 | W33: Private | X33: 0 | Y33: Valid | Z33: JAMMU | AA33: HYUNDAI MOTOR INDIA LTD | AB33: SANTRO GLS | AC33: =HYPERLINK(V33,"link") -> link
A34: 33 | B34: 0.81589198 | C34: 0.81554476 | D34: =C34-time(0,0,30) -> 0.81519753 | E34: =D35-D34 -> 0.00017084491 | F34: =D34-TIME(19,1,25) -> 0.022547072 | G34: Car | H34: J&K | I34: JK 02 DU 0772 | J34: 3 | K34: 0.81527778 | L34: =K34-TIME(19,1,25) -> 0.022627315 | M34: Petrol | N34: male | O34: 18.8 | P34: 1810 | Q34: Online | R34: NO | S34: 0.81716435 | T34: =S34-TIME(19,1,25) -> 0.024513889 | U34: =T34-L34 -> 0.0018865741 | V34: https://vehicleinfo.app/rc-details/JK02DU0772?rc_no=JK02DU0772 | W34: Private | X34: 0 | Y34: Valid | Z34: JAMMU | AA34: TOYOTA KIRLOSKAR MOTOR PVT LTD | AB34: ETIOS G PETROL KI | AC34: =HYPERLINK(V34,"link") -> link
A35: 34 | B35: 0.81606282 | C35: 0.8157156 | D35: =C35-time(0,0,30) -> 0.81536838 | E35: =D36-D35 -> 0.0013462037 | F35: =D35-TIME(19,1,25) -> 0.022717917 | G35: Car | H35: J&K | I35: JK 02 DC 5415 | J35: 2 | K35: 0.81736111 | L35: =K35-TIME(19,1,25) -> 0.024710648 | M35: Petrol | N35: male | O35: 5.18 | P35: 499.9736 | Q35: Offline | R35: NO | S35: 0.81818287 | T35: =S35-TIME(19,1,25) -> 0.025532407 | U35: =T35-L35 -> 0.00082175926 | V35: https://vehicleinfo.app/rc-details/JK02DC5415?rc_no=JK02DC5415 | W35: Private | X35: 0 | Y35: Valid | Z35: JAMMU | AA35: TATA MOTORS PASSENGER VEHICLES LTD | AB35: TIAGO XT NEW 1.2 RTN BS6 | AC35: =HYPERLINK(V35,"link") -> link
A36: 35 | B36: 0.81740903 | C36: 0.81706181 | D36: =C36-time(0,0,30) -> 0.81671458 | E36: =D37-D36 -> 0.0010214699 | F36: =D36-TIME(19,1,25) -> 0.02406412 | G36: Car | H36: J&K | I36: JK 02 DN 3352 | J36: 3 | K36: 0.81736111 | L36: =K36-TIME(19,1,25) -> 0.024710648 | M36: Petrol | N36: male | O36: 20.73 | P36: 2000 | Q36: Offline | R36: NO | S36: 0.81903935 | T36: =S36-TIME(19,1,25) -> 0.026388889 | U36: =T36-L36 -> 0.0016782407 | V36: https://vehicleinfo.app/rc-details/JK02DN3352?rc_no=JK02DN3352 | W36: Private | X36: 0 | Y36: Valid | Z36: JAMMU | AA36: MARUTI SUZUKI INDIA LTD | AB36: BREZZA LXI | AC36: =HYPERLINK(V36,"link") -> link
A37: 36 | B37: 0.8184305 | C37: 0.81808328 | D37: =C37-time(0,0,30) -> 0.81773605 | E37: =D38-D37 -> 0.00022131944 | F37: =D37-TIME(19,1,25) -> 0.02508559 | G37: trucks | H37: J&K | I37: JK 02 DK 0331 | J37: 1 | K37: 0.81875 | L37: =K37-TIME(19,1,25) -> 0.026099537 | M37: Diesel | N37: male | O37: 21.09 | P37: =O37*85.325 -> 1799.5042 | Q37: Offline | R37: NO | S37: 0.8208912 | T37: =S37-TIME(19,1,25) -> 0.028240741 | U37: =T37-L37 -> 0.0021412037 | V37: https://vehicleinfo.app/rc-details/JK02DK0331?rc_no=JK02DK0331 | W37: Private | X37: 0 | Y37: Valid | Z37: JAMMU | AA37: TATA MOTORS LTD | AB37: 407 GOLD SFC DCR33CBC 100B6M5 | AC37: =HYPERLINK(V37,"link") -> link
A38: 37 | B38: 0.81865182 | C38: 0.81830459 | D38: =C38-time(0,0,30) -> 0.81795737 | E38: =D39-D38 -> 0.00052998843 | F38: =D38-TIME(19,1,25) -> 0.02530691 | G38: Scooter | H38: J&K | I38: JK 02 BR 0955 | J38: 2 | K38: 0.81805556 | L38: =K38-TIME(19,1,25) -> 0.025405093 | M38: Petrol | N38: male | O38: 3.11 | P38: 300.1772 | Q38: Offline | R38: NO | S38: 0.81945602 | T38: =S38-TIME(19,1,25) -> 0.026805556 | U38: =T38-L38 -> 0.001400463 | V38: https://vehicleinfo.app/rc-details/JK02BR0955?rc_no=JK02BR0955 | W38: Private | X38: 0 | Y38: Expired | Z38: JAMMU | AA38: Hero MotoCorp Ltd | AB38: MESTRO EDGE | AC38: =HYPERLINK(V38,"link") -> link
A39: 38 | B39: 0.81918181 | C39: 0.81883458 | D39: =C39-time(0,0,30) -> 0.81848736 | E39: =D40-D39 -> 0.0010779977 | F39: =D39-TIME(19,1,25) -> 0.025836898 | G39: Car | H39: J&K | I39: JK 02 BW 6699 | J39: 3 | K39: 0.81875 | L39: =K39-TIME(19,1,25) -> 0.026099537 | M39: Petrol | N39: male | O39: 20.73 | P39: 2000 | Q39: CARD | R39: NO | S39: 0.82063657 | T39: =S39-TIME(19,1,25) -> 0.027986111 | U39: =T39-L39 -> 0.0018865741 | V39: https://vehicleinfo.app/rc-details/JK02BW6699?rc_no=JK02BW6699 | W39: Private | X39: 0 | Y39: Expired | Z39: JAMMU | AA39: HYUNDAI MOTOR INDIA LTD | AB39: I20 ASTA (O) VTVT | AC39: =HYPERLINK(V39,"link") -> link
A40: 39 | B40: 0.8202598 | C40: 0.81991258 | D40: =C40-time(0,0,30) -> 0.81956536 | E40: =D41-D40 -> 0.003611632 | F40: =D40-TIME(19,1,25) -> 0.026914896 | G40: Car | H40: J&K | I40: JK 02 CA 5999 | J40: 3 | K40: 0.82013889 | L40: =K40-TIME(19,1,25) -> 0.027488426 | M40: Petrol | N40: male | O40: 2.07 | P40: 199.7964 | Q40: Offilne | R40: Yes | S40: 0.82215278 | T40: =S40-TIME(19,1,25) -> 0.029502315 | U40: =T40-L40 -> 0.0020138889 | V40: https://vehicleinfo.app/rc-details/JK02CA5999?rc_no=JK02CA5999 | W40: Private | X40: 3 | Y40: Valid | Z40: JAMMU | AA40: MARUTI SUZUKI INDIA LTD | AB40: MARUTI CIAZ ALPHA | AC40: =HYPERLINK(V40,"link") -> link
...

Sheet Range Tables
A2: Pump Number Distribution
A3: Petrol
A4: Sl.no | B4: Pump Number | C4: Frequency | D4: Probability | E4: Cumulative Probability | F4: Lower range | G4: Higher range
A5: 1 | B5: 2 | C5: 46 | D5: =C5/$C$8 -> 0.52272727 | E5: 0.52272727 | F5: 0 | G5: =E5-0.001 -> 0.52172727
A6: 2 | B6: 3 | C6: 28 | D6: =C6/$C$8 -> 0.31818182 | E6: =E5+D6 -> 0.84090909 | F6: 0.52272727 | G6: =E6-0.001 -> 0.83990909
A7: 3 | B7: 4 | C7: 14 | D7: =C7/$C$8 -> 0.15909091 | E7: =E6+D7 -> 1 | F7: 0.84090909 | G7: =E7-0.001 -> 0.999
B8: Total | C8: =SUM(C5:C7) -> 88 | D8: =SUM(D5:D7) -> 1
A10: Pump Number Distribution
A11: Diesel
A12: Sl.no | B12: Pump Number | C12: Frequency | D12: Probability | E12: Cumulative Probability | F12: Lower range | G12: Higher range
A13: 1 | B13: 1 | C13: 13 | D13: =C13/C15 -> 0.86666667 | E13: 0.86666667 | F13: 0 | G13: =E13-0.001 -> 0.86566667
A14: 2 | B14: 5 | C14: 2 | D14: =C14/C15 -> 0.13333333 | E14: =E13+D14 -> 1 | F14: 0.86666667 | G14: =E14-0.001 -> 0.999
B15: Total | C15: =sum(C13:C14) -> 15 | D15: =sum(D13:D14) -> 1
A16: Vehicle to Fuel Distribution
A17: Car | K17: Fuel Type Distribution
A18: Sl.no | B18: Fuel type | C18: Frequency | D18: Probability | E18: Cumulative Probability | F18: Lower range | G18: Higher range | K18: Sl.no | L18: fuel type | M18: frequency | N18: probality | O18: cumulative probility | P18: Lower range | Q18: Higher range
A19: 1 | B19: Petrol | C19: 44 | D19: =C19/C$21 -> 0.89795918 | E19: 0.89795918 | F19: 0 | G19: =E19-0.001 -> 0.89695918 | K19: 1 | L19: petrol | M19: 88 | N19: =M19/M$21 -> 0.85436893 | O19: 0.854 | P19: 0 | Q19: =O19-0.001 -> 0.853
A20: 2 | B20: Diesel | C20: 5 | D20: =C20/C$21 -> 0.10204082 | E20: =E19+D20 -> 1 | F20: 0.89795918 | G20: =E20-0.001 -> 0.999 | K20: 2 | L20: desiel | M20: 15 | N20: =M20/M$21 -> 0.14563107 | O20: 1 | P20: 0.854 | Q20: =O20-0.001 -> 0.999
B21: Total | C21: =sum(C19:C20) -> 49 | D21: =C21/C$21 -> 1 | L21: total | M21: =SUM(M19:M20) -> 103 | N21: =M21/M$21 -> 1
A22: Vehicle to Fuel Distribution | L22: Diesel
A23: Bike | K23: Sl.no | L23: Vehicle Type | M23: frequency | N23: probality | O23: cumulative probility | P23: Lower range | Q23: Higher range
A24: Sl.no | B24: Fuel type | C24: Frequency | D24: Probability | E24: Cumulative Probability | F24: Lower range | G24: Higher range | K24: 1 | L24: Car | M24: 5 | N24: =M24/M$28 -> 0.33333333 | O24: =0+N24 -> 0.33333333 | P24: 0 | Q24: =O24-0.001 -> 0.33233333
A25: 1 | B25: Petrol | C25: 29 | D25: =C25/C$27 -> 1 | E25: 1 | F25: 0 | G25: =E25-0.001 -> 0.999 | K25: 2 | L25: Auto | M25: 3 | N25: =M25/M$28 -> 0.2 | O25: =(O24+N25) -> 0.53333333 | P25: 0.33333333 | Q25: =O25-0.001 -> 0.53233333
A26: 2 | B26: Diesel | C26: 0 | D26: =C26/C$27 -> 0 | E26: =E25+D26 -> 1 | F26: – | G26: – | K26: 3 | L26: Carriers* | M26: 5 | N26: =M26/M$28 -> 0.33333333 | O26: =(O25+N26) -> 0.86666667 | P26: 0.53333333 | Q26: =O26-0.001 -> 0.86566667
B27: Total | C27: =sum(C25:C26) -> 29 | D27: =C27/C$27 -> 1 | K27: 4 | L27: Van* | M27: 2 | N27: =M27/M$28 -> 0.13333333 | O27: =(O26+N27) -> 1 | P27: 0.86666667 | Q27: =O27-0.001 -> 0.999
A28: Vehicle to Fuel Distribution | L28: total | M28: =sum(M24:M27) -> 15 | N28: =M28/M$28 -> 1
A29: Scooter | K29: Petrol
A30: Sl.no | B30: Fuel type | C30: Frequency | D30: Probability | E30: Cumulative Probability | F30: Lower range | G30: Higher range | K30: Sl.no | L30: Vehicle Type | M30: frequency | N30: probality | O30: cumulative probility | P30: Lower range | Q30: Higher range
A31: 1 | B31: Petrol | C31: 8 | D31: =C31/C$33 -> 1 | E31: 1 | F31: 0 | G31: =E31-0.001 -> 0.999 | K31: 1 | L31: Car | M31: 44 | N31: =M31/M$36 -> 0.5 | O31: 0.5 | P31: 0 | Q31: =O31-0.001 -> 0.499
A32: 2 | B32: Diesel | C32: 0 | D32: =C32/C$33 -> 0 | E32: =E31+D32 -> 1 | F32: – | G32: – | K32: 2 | L32: Bike | M32: 29 | N32: =M32/M$36 -> 0.32954545 | O32: =(O31+N32) -> 0.82954545 | P32: 0.5 | Q32: =O32-0.001 -> 0.82854545
B33: Total | C33: =SUM(C31:C32) -> 8 | D33: =C33/C$33 -> 1 | K33: 3 | L33: Scooter | M33: 8 | N33: =M33/M$36 -> 0.090909091 | O33: =(O32+N33) -> 0.92045455 | P33: 0.82954545 | Q33: =O33-0.001 -> 0.91945455
A34: Vehicle to Fuel Distribution | K34: 4 | L34: Auto | M34: 4 | N34: =M34/M$36 -> 0.045454545 | O34: =(O33+N34) -> 0.96590909 | P34: 0.92045455 | Q34: =O34-0.001 -> 0.96490909
A35: Auto | K35: 5 | L35: Carriers* | M35: 3 | N35: =M35/M$36 -> 0.034090909 | O35: =(O34+N35) -> 1 | P35: 0.96590909 | Q35: =O35-0.001 -> 0.999
A36: Sl.no | B36: Fuel type | C36: Frequency | D36: Probability | E36: Cumulative Probability | F36: Lower range | G36: Higher range | L36: Total | M36: =sum(M31:M35) -> 88 | N36: =M36/M$36 -> 1
A37: 1 | B37: Petrol | C37: 4 | D37: =C37/C$39 -> 0.57142857 | E37: 0.57142857 | F37: 0 | G37: =E37-0.001 -> 0.57042857
A38: 2 | B38: Diesel | C38: 3 | D38: =C38/C$39 -> 0.42857143 | E38: =E37+D38 -> 1 | F38: 0.57142857 | G38: =E38-0.001 -> 0.999
B39: Total | C39: =sum(C37:C38) -> 7 | D39: =C39/C$39 -> 1
A40: Vehicle to Fuel Distribution
A41: Carriers*
A42: Sl.no | B42: Fuel type | C42: Frequency | D42: Probability | E42: Cumulative Probability | F42: Lower range | G42: Higher range
...

Sheet Simulation
A1: PCT PROJECT — Monte Carlo Simulation (200 Customers)
A2: No. | B2: Inter-Arrival Time | G2: Vehicle Type | I2: Fuel Type | K2: Pump | M2: Service Time | R2: Clock | T2: Pump1 | AA2: Pump 2 | AH2: pump 3 | AO2: pump 4 | AV2: pump5 | BC2: mode of payment | BE2: City of Registration | BG2: No. of Chalans Pending | BI2: Insurance Status
B3: Rand | C3: Range | D3: a | E3: b | F3: Seconds | G3: Rand | H3: Vehicle | I3: Rand | K3: Rand | L3: Pump Number | M3: rand | N3: Range | O3: a | P3: b | Q3: Seconds | R3: Time | S3: time | T3: Status | U3: Waiting Time | V3: waiting | W3: Service Start Time | X3: sst | Y3: Service End Time | Z3: set | AA3: status | AB3: Waiting Time | AC3: waiting | AD3: Service Start Time | AE3: sst | AF3: Service End Time | AG3: set | AH3: status | AI3: Waiting Time | AJ3: waiting | AK3: Service Start Time | AL3: sst | AM3: Service End Time | AN3: set | AO3: status | AP3: Waiting Time | AQ3: waiting | AR3: Service Start Time | AS3: sst | AT3: Service End Time | AU3: set | AV3: status | AW3: Waiting Time | AX3: waiting | AY3: Service Start Time | AZ3: sst | BA3: Service End Time | BB3: set | BC3: Rand | BD3: Payment Mode | BE3: Rand | BF3: City | BG3: Rand | BH3: No. Chalans | BI3: Rand
A4: 1 | B4: 0.38425736 | C4: =ifs(B4<='Range Tables'!$G$54,'Range Tables'!$B$54,B4<='Range Tables'!$G$55,'Range Tables'!$B$55,B4<='Range Tables'!$G$56,'Range Tables'!$B$56,B4<='Range Tables'!$G$57,'Range Tables'!$B$57,B4<='Range Tables'!$G$58,'Range Tables'!$B$58,B4<='Range Tables'!$G$59,'Range Tables'!$B$59,B4<='Range Tables'!$G$60,'Range Tables'!$B$60,B4<='Range Tables'!$G$61,'Range Tables'!$B$61,B4<='Range Tables'!$G$63,'Range Tables'!$B$63,B4<='Range Tables'!$G$64,'Range Tables'!$B$64,B4<='Range Tables'!$G$66,'Range Tables'!$B$66) -> 30 - 60 | D4: =IFERROR(__xludf.DUMMYFUNCTION("SPLIT(C4,""-"")"),30.0) -> 30 | E4: =IFERROR(__xludf.DUMMYFUNCTION("""COMPUTED_VALUE"""),60.0) -> 60 | F4: =D4+B4*(E4-D4) -> 41.527721 | G4: 0.34423349 | H4: =ifs(G4<='Range Tables'!$G$86,'Range Tables'!$B$86,G4<='Range Tables'!$G$87,'Range Tables'!$B$87,G4<='Range Tables'!$G$88,'Range Tables'!$B$88,G4<='Range Tables'!$G$89,'Range Tables'!$B$89,G4<='Range Tables'!$G$90,'Range Tables'!$B$90,G4<='Range Tables'!$G$91,'Range Tables'!$B$91) -> Car | I4: 0.77469372 | J4: =IFS( H4="Car", IF(I4<='Range Tables'!$G$19, 'Range Tables'!$B$19, 'Range Tables'!$B$20), H4="Bike", IF(I4<='Range Tables'!$G$25, 'Range Tables'!$B$25, 'Range Tables'!$B$26), H4="Scooter", IF(I4<='Range Tables'!$G$31, 'Range Tables'!$B$31, 'Range Tables'!$B$32), H4="Auto", IF(I4<='Range Tables'!$G$37, 'Range Tables'!$B$37, 'Range Tables'!$B$38), H4="Carriers*", IF(I4<='Range Tables'!$G$43, 'Range Tables'!$B$43, 'Range Tables'!$B$44), H4="Van*", IF(I4<='Range Tables'!$G$50, 'Range Tables'!$B$50, 'Range Tables'!$B$49) ) -> Petrol | K4: 0.49953312 | L4: =if(J4="Petrol",ifs(K4<='Range Tables'!$G$5,'Range Tables'!$B$5,K4<='Range Tables'!$G$6,'Range Tables'!$B$6,K4<='Range Tables'!$G$7,'Range Tables'!$B$7),ifs(K4<='Range Tables'!$G$13,'Range Tables'!$B$13,K4<='Range Tables'!$G$14,'Range Tables'!$B$14)) -> 2 | M4: 0.42969866 | N4: =ifs(H4="Car",ifs(M4<='Range Tables'!$G$125,'Range Tables'!$B$125,M4<='Range Tables'!$G$126,'Range Tables'!$B$126,M4<='Range Tables'!$G$127,'Range Tables'!$B$127,M4<='Range Tables'!$G$128,'Range Tables'!$B$128,M4<='Range Tables'!$G$129,'Range Tables'!$B$129,'Range Tables'!$G$131,'Range Tables'!$B$131),H4="Bike",ifs(M4<='Range Tables'!$G$136,'Range Tables'!$B$136,M4<='Range Tables'!$G$137,'Range Tables'!$B$137,M4<='Range Tables'!$G$138,'Range Tables'!$B$138,M4<='Range Tables'!$G$142,'Range Tables'!$B$142),H4="Scooter",ifs(M4<='Range Tables'!$G$148,'Range Tables'!$B$148,M4<='Range Tables'!$G$149,'Range Tables'!$B$149,M4<='Range Tables'!$G$150,'Range Tables'!$B$150,M4<='Range Tables'!$G$151,'Range Tables'!$B$151),H4="Auto",ifs(M4<='Range Tables'!$G$161,'Range Tables'!$B$161,M4<='Range Tables'!$G$162,'Range Tables'!$B$162,M4<='Range Tables'!$G$163,'Range Tables'!$B$163,M4<='Range Tables'!$G$164,'Range Tables'!$B$164),H4="Carriers*",ifs(M4<='Range Tables'!$G$173,'Range Tables'!$B$173,M4<='Range Tables'!$G$174,'Range Tables'!$B$174,M4<='Range Tables'!$G$175,'Range Tables'!$B$175,M4<='Range Tables'!$G$176,'Range Tables'!$B$176,M4<='Range Tables'!$G$177,'Range Tables'!$B$177,M4<='Range Tables'!$G$179,'Range Tables'!$B$179),H4="Van*",ifs(M4<='Range Tables'!$G$186,'Range Tables'!$B$186)) -> 60 - 120 | O4: =IFERROR(__xludf.DUMMYFUNCTION("SPLIT(N4,""-"")"),60.0) -> 60 | P4: =IFERROR(__xludf.DUMMYFUNCTION("""COMPUTED_VALUE"""),120.0) -> 120 | Q4: =O4+M4*(P4-O4) -> 85.78192 | R4: =S4/86400 -> 0 | S4: 0 | T4: =if(L4=1,"yes","no") -> no | U4: =V4/86400 -> 0 | V4: 0 | W4: =X4/86400 -> 0 | X4: =if(T4="yes",S4+V4,0) -> 0 | Y4: =Z4/86400 -> 0 | Z4: =if(T4="yes",Q4+X4,0) -> 0 | AA4: =IF(L4=2,"yes","no") -> yes | AB4: =AC4/86400 -> 0 | AC4: 0 | AD4: =AE4/86400 -> 0 | AE4: =if(AA4="yes",S4+AC4,0) -> 0 | AF4: =AG4/86400 -> 0.00099284629 | AG4: =if(AA4="yes",Q4+AE4,0) -> 85.78192 | AH4: =IF(L4=3,"yes","no") -> no | AI4: =AJ4/86400 -> 0 | AJ4: 0 | AK4: =AL4/86400 -> 0 | AL4: =if(AH4="yes",AJ4+S4,0) -> 0 | AM4: =AN4/86400 -> 0 | AN4: =if(AH4="yes",AL4+Q4,0) -> 0 | AO4: =if(L4=4,"yes","no") -> no | AP4: =AQ4/86400 -> 0 | AQ4: 0 | AR4: =AS4/86400 -> 0 | AS4: =if(AO4="yes",AQ4+S4,0) -> 0 | AT4: =AU4/86400 -> 0 | AU4: =if(AO4="yes",AS4+Q4,0) -> 0 | AV4: =if(L4=5,"yes","no") -> no | AW4: =AX4/86400 -> 0 | AX4: 0 | AY4: =AZ4/86400 -> 0 | AZ4: =if(AV4="yes",AX4+S4,0) -> 0 | BA4: =BB4/86400 -> 0 | BB4: =if(AV4="yes",AZ4+Q4,0) -> 0 | BC4: 0.32331865 | BD4: =ifs(BC4<='Range Tables'!$G$81,'Range Tables'!$B$81,BC4<='Range Tables'!$G$82,'Range Tables'!$B$82) -> Online* | BE4: 0.56940469 | BF4: =ifs(BE4<='Range Tables'!$G$95,'Range Tables'!$B$95,BE4<='Range Tables'!$G$96,'Range Tables'!$B$96,BE4<='Range Tables'!$G$97,'Range Tables'!$B$97,BE4<='Range Tables'!$G$98,'Range Tables'!$B$98,BE4<='Range Tables'!$G$99,'Range Tables'!$B$99,BE4<='Range Tables'!$G$100,'Range Tables'!$B$100,BE4<='Range Tables'!$G$101,'Range Tables'!$B$101,BE4<='Range Tables'!$G$102,'Range Tables'!$B$102,BE4<='Range Tables'!$G$103,'Range Tables'!$B$103) -> Jammu | BG4: 0.31017479 | BH4: =ifs(BG4<='Range Tables'!$G$112,'Range Tables'!$B$112,BG4<='Range Tables'!$G$113,'Range Tables'!$B$113,BG4<='Range Tables'!$G$114,'Range Tables'!$B$114) -> 0 | BI4: 0.79338008 | BJ4: =ifs(BI4<='Range Tables'!$G$118,'Range Tables'!$B$118,BI4<='Range Tables'!$G$119,'Range Tables'!$B$119) -> Expired
A5: 2 | B5: 0.58111903 | C5: =ifs(B5<='Range Tables'!$G$54,'Range Tables'!$B$54,B5<='Range Tables'!$G$55,'Range Tables'!$B$55,B5<='Range Tables'!$G$56,'Range Tables'!$B$56,B5<='Range Tables'!$G$57,'Range Tables'!$B$57,B5<='Range Tables'!$G$58,'Range Tables'!$B$58,B5<='Range Tables'!$G$59,'Range Tables'!$B$59,B5<='Range Tables'!$G$60,'Range Tables'!$B$60,B5<='Range Tables'!$G$61,'Range Tables'!$B$61,B5<='Range Tables'!$G$63,'Range Tables'!$B$63,B5<='Range Tables'!$G$64,'Range Tables'!$B$64,B5<='Range Tables'!$G$66,'Range Tables'!$B$66) -> 60 - 90 | D5: =IFERROR(__xludf.DUMMYFUNCTION("SPLIT(C5,""-"")"),60.0) -> 60 | E5: =IFERROR(__xludf.DUMMYFUNCTION("""COMPUTED_VALUE"""),90.0) -> 90 | F5: =D5+B5*(E5-D5) -> 77.433571 | G5: 0.17213583 | H5: =ifs(G5<='Range Tables'!$G$86,'Range Tables'!$B$86,G5<='Range Tables'!$G$87,'Range Tables'!$B$87,G5<='Range Tables'!$G$88,'Range Tables'!$B$88,G5<='Range Tables'!$G$89,'Range Tables'!$B$89,G5<='Range Tables'!$G$90,'Range Tables'!$B$90,G5<='Range Tables'!$G$91,'Range Tables'!$B$91) -> Car | I5: 0.055465392 | J5: =IFS( H5="Car", IF(I5<='Range Tables'!$G$19, 'Range Tables'!$B$19, 'Range Tables'!$B$20), H5="Bike", IF(I5<='Range Tables'!$G$25, 'Range Tables'!$B$25, 'Range Tables'!$B$26), H5="Scooter", IF(I5<='Range Tables'!$G$31, 'Range Tables'!$B$31, 'Range Tables'!$B$32), H5="Auto", IF(I5<='Range Tables'!$G$37, 'Range Tables'!$B$37, 'Range Tables'!$B$38), H5="Carriers*", IF(I5<='Range Tables'!$G$43, 'Range Tables'!$B$43, 'Range Tables'!$B$44), H5="Van*", IF(I5<='Range Tables'!$G$50, 'Range Tables'!$B$50, 'Range Tables'!$B$49) ) -> Petrol | K5: 0.19690499 | L5: =if(J5="Petrol",ifs(K5<='Range Tables'!$G$5,'Range Tables'!$B$5,K5<='Range Tables'!$G$6,'Range Tables'!$B$6,K5<='Range Tables'!$G$7,'Range Tables'!$B$7),ifs(K5<='Range Tables'!$G$13,'Range Tables'!$B$13,K5<='Range Tables'!$G$14,'Range Tables'!$B$14)) -> 2 | M5: 0.65003702 | N5: =ifs(H5="Car",ifs(M5<='Range Tables'!$G$125,'Range Tables'!$B$125,M5<='Range Tables'!$G$126,'Range Tables'!$B$126,M5<='Range Tables'!$G$127,'Range Tables'!$B$127,M5<='Range Tables'!$G$128,'Range Tables'!$B$128,M5<='Range Tables'!$G$129,'Range Tables'!$B$129,'Range Tables'!$G$131,'Range Tables'!$B$131),H5="Bike",ifs(M5<='Range Tables'!$G$136,'Range Tables'!$B$136,M5<='Range Tables'!$G$137,'Range Tables'!$B$137,M5<='Range Tables'!$G$138,'Range Tables'!$B$138,M5<='Range Tables'!$G$142,'Range Tables'!$B$142),H5="Scooter",ifs(M5<='Range Tables'!$G$148,'Range Tables'!$B$148,M5<='Range Tables'!$G$149,'Range Tables'!$B$149,M5<='Range Tables'!$G$150,'Range Tables'!$B$150,M5<='Range Tables'!$G$151,'Range Tables'!$B$151),H5="Auto",ifs(M5<='Range Tables'!$G$161,'Range Tables'!$B$161,M5<='Range Tables'!$G$162,'Range Tables'!$B$162,M5<='Range Tables'!$G$163,'Range Tables'!$B$163,M5<='Range Tables'!$G$164,'Range Tables'!$B$164),H5="Carriers*",ifs(M5<='Range Tables'!$G$173,'Range Tables'!$B$173,M5<='Range Tables'!$G$174,'Range Tables'!$B$174,M5<='Range Tables'!$G$175,'Range Tables'!$B$175,M5<='Range Tables'!$G$176,'Range Tables'!$B$176,M5<='Range Tables'!$G$177,'Range Tables'!$B$177,M5<='Range Tables'!$G$179,'Range Tables'!$B$179),H5="Van*",ifs(M5<='Range Tables'!$G$186,'Range Tables'!$B$186)) -> 120 - 180 | O5: =IFERROR(__xludf.DUMMYFUNCTION("SPLIT(N5,""-"")"),120.0) -> 120 | P5: =IFERROR(__xludf.DUMMYFUNCTION("""COMPUTED_VALUE"""),180.0) -> 180 | Q5: =O5+M5*(P5-O5) -> 159.00222 | R5: =S5/86400 -> 0.00048064492 | S5: 41.527721 | T5: =if(L5=1,"yes","no") -> no | U5: =V5/86400 -> 0 | V5: =if(T5="yes", if(Z4>S5,Z4-S5,0),0) -> 0 | W5: =X5/86400 -> 0 | X5: =if(T5="yes",S5+V5,0) -> 0 | Y5: =Z5/86400 -> 0 | Z5: =if(T5="yes",Q5+X5,0) -> 0 | AA5: =IF(L5=2,"yes","no") -> yes | AB5: =AC5/86400 -> 0.00051220138 | AC5: =if(AA5="yes", if(AG4>S5,AG4-S5,0),0) -> 44.254199 | AD5: =AE5/86400 -> 0.00099284629 | AE5: =if(AA5="yes",S5+AC5,0) -> 85.78192 | AF5: =AG5/86400 -> 0.0028331498 | AG5: =if(AA5="yes",Q5+AE5,0) -> 244.78414 | AH5: =IF(L5=3,"yes","no") -> no | AI5: =AJ5/86400 -> 0 | AJ5: =if(AH5="yes", if(AN4>S5,AN4-S5,0),0) -> 0 | AK5: =AL5/86400 -> 0 | AL5: =if(AH5="yes",AJ5+S5,0) -> 0 | AM5: =AN5/86400 -> 0 | AN5: =if(AH5="yes",AL5+Q5,0) -> 0 | AO5: =if(L5=4,"yes","no") -> no | AP5: =AQ5/86400 -> 0 | AQ5: =if(AO5="yes",if(AU4>S5,AU4-S5,0),0) -> 0 | AR5: =AS5/86400 -> 0 | AS5: =if(AO5="yes",AQ5+S5,0) -> 0 | AT5: =AU5/86400 -> 0 | AU5: =if(AO5="yes",AS5+Q5,0) -> 0 | AV5: =if(L5=5,"yes","no") -> no | AW5: =AX5/86400 -> 0 | AX5: =if(AV5="yes",if(BB4>S5,BB5-S5,0),0) -> 0 | AY5: =AZ5/86400 -> 0 | AZ5: =if(AV5="yes",AX5+S5,0) -> 0 | BA5: =BB5/86400 -> 0 | BB5: =if(AV5="yes",AZ5+Q5,0) -> 0 | BC5: 0.41881958 | BD5: =ifs(BC5<='Range Tables'!$G$81,'Range Tables'!$B$81,BC5<='Range Tables'!$G$82,'Range Tables'!$B$82) -> Offline* | BE5: 0.81587617 | BF5: =ifs(BE5<='Range Tables'!$G$95,'Range Tables'!$B$95,BE5<='Range Tables'!$G$96,'Range Tables'!$B$96,BE5<='Range Tables'!$G$97,'Range Tables'!$B$97,BE5<='Range Tables'!$G$98,'Range Tables'!$B$98,BE5<='Range Tables'!$G$99,'Range Tables'!$B$99,BE5<='Range Tables'!$G$100,'Range Tables'!$B$100,BE5<='Range Tables'!$G$101,'Range Tables'!$B$101,BE5<='Range Tables'!$G$102,'Range Tables'!$B$102,BE5<='Range Tables'!$G$103,'Range Tables'!$B$103) -> Other State Cities | BG5: 0.48245089 | BH5: =ifs(BG5<='Range Tables'!$G$112,'Range Tables'!$B$112,BG5<='Range Tables'!$G$113,'Range Tables'!$B$113,BG5<='Range Tables'!$G$114,'Range Tables'!$B$114) -> 0 | BI5: 0.584073 | BJ5: =ifs(BI5<='Range Tables'!$G$118,'Range Tables'!$B$118,BI5<='Range Tables'!$G$119,'Range Tables'!$B$119) -> Valid
